<?xml version="1.0" encoding="UTF-8"?>
<testng-results skipped="0" failed="2" total="6" passed="4">
  <reporter-output>
  </reporter-output>
  <suite name="Default suite" duration-ms="1089" started-at="2019-02-23T01:35:25Z" finished-at="2019-02-23T01:35:26Z">
    <groups>
    </groups>
    <test name="Default test" duration-ms="1089" started-at="2019-02-23T01:35:25Z" finished-at="2019-02-23T01:35:26Z">
      <class name="daotests.CustomerDAOTesting">
        <test-method status="PASS" signature="testAddUser()[pri:0, instance:daotests.CustomerDAOTesting@27a0a5a2]" name="testAddUser" duration-ms="346" started-at="2019-02-22T20:35:25Z" finished-at="2019-02-22T20:35:25Z">
          <reporter-output>
          </reporter-output>
        </test-method> <!-- testAddUser -->
        <test-method status="FAIL" signature="testGetCustomerExisitingUsername()[pri:1, instance:daotests.CustomerDAOTesting@27a0a5a2]" name="testGetCustomerExisitingUsername" duration-ms="15" started-at="2019-02-22T20:35:25Z" finished-at="2019-02-22T20:35:25Z">
          <exception class="java.lang.AssertionError">
            <message>
              <![CDATA[expected [model.Customer@36a7abe1] but found [null]]]>
            </message>
            <full-stacktrace>
              <![CDATA[java.lang.AssertionError: expected [model.Customer@36a7abe1] but found [null]
	at org.testng.Assert.fail(Assert.java:94)
	at org.testng.Assert.failNotEquals(Assert.java:513)
	at org.testng.Assert.assertEqualsImpl(Assert.java:130)
	at org.testng.Assert.assertEquals(Assert.java:116)
	at org.testng.Assert.assertEquals(Assert.java:179)
	at daotests.CustomerDAOTesting.testGetCustomerExisitingUsername(CustomerDAOTesting.java:44)
	at sun.reflect.NativeMethodAccessorImpl.invoke0(Native Method)
	at sun.reflect.NativeMethodAccessorImpl.invoke(Unknown Source)
	at sun.reflect.DelegatingMethodAccessorImpl.invoke(Unknown Source)
	at java.lang.reflect.Method.invoke(Unknown Source)
	at org.testng.internal.MethodInvocationHelper.invokeMethod(MethodInvocationHelper.java:86)
	at org.testng.internal.Invoker.invokeMethod(Invoker.java:643)
	at org.testng.internal.Invoker.invokeTestMethod(Invoker.java:820)
	at org.testng.internal.Invoker.invokeTestMethods(Invoker.java:1128)
	at org.testng.internal.TestMethodWorker.invokeTestMethods(TestMethodWorker.java:129)
	at org.testng.internal.TestMethodWorker.run(TestMethodWorker.java:112)
	at org.testng.TestRunner.privateRun(TestRunner.java:782)
	at org.testng.TestRunner.run(TestRunner.java:632)
	at org.testng.SuiteRunner.runTest(SuiteRunner.java:366)
	at org.testng.SuiteRunner.runSequentially(SuiteRunner.java:361)
	at org.testng.SuiteRunner.privateRun(SuiteRunner.java:319)
	at org.testng.SuiteRunner.run(SuiteRunner.java:268)
	at org.testng.SuiteRunnerWorker.runSuite(SuiteRunnerWorker.java:52)
	at org.testng.SuiteRunnerWorker.run(SuiteRunnerWorker.java:86)
	at org.testng.TestNG.runSuitesSequentially(TestNG.java:1244)
	at org.testng.TestNG.runSuitesLocally(TestNG.java:1169)
	at org.testng.TestNG.run(TestNG.java:1064)
	at org.testng.remote.AbstractRemoteTestNG.run(AbstractRemoteTestNG.java:114)
	at org.testng.remote.RemoteTestNG.initAndRun(RemoteTestNG.java:251)
	at org.testng.remote.RemoteTestNG.main(RemoteTestNG.java:77)
]]>
            </full-stacktrace>
          </exception> <!-- java.lang.AssertionError -->
          <reporter-output>
          </reporter-output>
        </test-method> <!-- testGetCustomerExisitingUsername -->
        <test-method status="PASS" signature="testGetCustomerNonexistantUsername()[pri:1, instance:daotests.CustomerDAOTesting@27a0a5a2]" name="testGetCustomerNonexistantUsername" duration-ms="320" started-at="2019-02-22T20:35:25Z" finished-at="2019-02-22T20:35:26Z">
          <reporter-output>
          </reporter-output>
        </test-method> <!-- testGetCustomerNonexistantUsername -->
        <test-method status="PASS" signature="LoginWithInvalidCredentials()[pri:2, instance:daotests.CustomerDAOTesting@27a0a5a2]" name="LoginWithInvalidCredentials" duration-ms="292" started-at="2019-02-22T20:35:26Z" finished-at="2019-02-22T20:35:26Z">
          <reporter-output>
          </reporter-output>
        </test-method> <!-- LoginWithInvalidCredentials -->
        <test-method status="FAIL" signature="LoginWithValidCredentials()[pri:2, instance:daotests.CustomerDAOTesting@27a0a5a2]" name="LoginWithValidCredentials" duration-ms="30" started-at="2019-02-22T20:35:26Z" finished-at="2019-02-22T20:35:26Z">
          <exception class="java.lang.AssertionError">
            <message>
              <![CDATA[expected [true] but found [false]]]>
            </message>
            <full-stacktrace>
              <![CDATA[java.lang.AssertionError: expected [true] but found [false]
	at org.testng.Assert.fail(Assert.java:94)
	at org.testng.Assert.failNotEquals(Assert.java:513)
	at org.testng.Assert.assertEqualsImpl(Assert.java:135)
	at org.testng.Assert.assertEquals(Assert.java:116)
	at org.testng.Assert.assertEquals(Assert.java:305)
	at org.testng.Assert.assertEquals(Assert.java:315)
	at daotests.CustomerDAOTesting.LoginWithValidCredentials(CustomerDAOTesting.java:59)
	at sun.reflect.NativeMethodAccessorImpl.invoke0(Native Method)
	at sun.reflect.NativeMethodAccessorImpl.invoke(Unknown Source)
	at sun.reflect.DelegatingMethodAccessorImpl.invoke(Unknown Source)
	at java.lang.reflect.Method.invoke(Unknown Source)
	at org.testng.internal.MethodInvocationHelper.invokeMethod(MethodInvocationHelper.java:86)
	at org.testng.internal.Invoker.invokeMethod(Invoker.java:643)
	at org.testng.internal.Invoker.invokeTestMethod(Invoker.java:820)
	at org.testng.internal.Invoker.invokeTestMethods(Invoker.java:1128)
	at org.testng.internal.TestMethodWorker.invokeTestMethods(TestMethodWorker.java:129)
	at org.testng.internal.TestMethodWorker.run(TestMethodWorker.java:112)
	at org.testng.TestRunner.privateRun(TestRunner.java:782)
	at org.testng.TestRunner.run(TestRunner.java:632)
	at org.testng.SuiteRunner.runTest(SuiteRunner.java:366)
	at org.testng.SuiteRunner.runSequentially(SuiteRunner.java:361)
	at org.testng.SuiteRunner.privateRun(SuiteRunner.java:319)
	at org.testng.SuiteRunner.run(SuiteRunner.java:268)
	at org.testng.SuiteRunnerWorker.runSuite(SuiteRunnerWorker.java:52)
	at org.testng.SuiteRunnerWorker.run(SuiteRunnerWorker.java:86)
	at org.testng.TestNG.runSuitesSequentially(TestNG.java:1244)
	at org.testng.TestNG.runSuitesLocally(TestNG.java:1169)
	at org.testng.TestNG.run(TestNG.java:1064)
	at org.testng.remote.AbstractRemoteTestNG.run(AbstractRemoteTestNG.java:114)
	at org.testng.remote.RemoteTestNG.initAndRun(RemoteTestNG.java:251)
	at org.testng.remote.RemoteTestNG.main(RemoteTestNG.java:77)
]]>
            </full-stacktrace>
          </exception> <!-- java.lang.AssertionError -->
          <reporter-output>
          </reporter-output>
        </test-method> <!-- LoginWithValidCredentials -->
        <test-method status="PASS" signature="testUpdateCustomer()[pri:3, instance:daotests.CustomerDAOTesting@27a0a5a2]" name="testUpdateCustomer" duration-ms="53" started-at="2019-02-22T20:35:26Z" finished-at="2019-02-22T20:35:26Z">
          <reporter-output>
          </reporter-output>
        </test-method> <!-- testUpdateCustomer -->
        <test-method status="FAIL" signature="deleteUser()[pri:0, instance:daotests.CustomerDAOTesting@27a0a5a2]" name="deleteUser" is-config="true" duration-ms="0" started-at="2019-02-22T20:35:26Z" finished-at="2019-02-22T20:35:26Z">
          <exception class="java.lang.IllegalArgumentException">
            <message>
              <![CDATA[org.hibernate.hql.internal.ast.QuerySyntaxException: customer is not mapped [delete from customer where username = 'username']]]>
            </message>
            <full-stacktrace>
              <![CDATA[java.lang.IllegalArgumentException: org.hibernate.hql.internal.ast.QuerySyntaxException: customer is not mapped [delete from customer where username = 'username']
	at org.hibernate.internal.ExceptionConverterImpl.convert(ExceptionConverterImpl.java:131)
	at org.hibernate.internal.ExceptionConverterImpl.convert(ExceptionConverterImpl.java:155)
	at org.hibernate.internal.ExceptionConverterImpl.convert(ExceptionConverterImpl.java:162)
	at org.hibernate.internal.AbstractSharedSessionContract.createQuery(AbstractSharedSessionContract.java:662)
	at org.hibernate.internal.AbstractSharedSessionContract.createQuery(AbstractSharedSessionContract.java:102)
	at daotests.CustomerDAOTesting.deleteUser(CustomerDAOTesting.java:88)
	at sun.reflect.NativeMethodAccessorImpl.invoke0(Native Method)
	at sun.reflect.NativeMethodAccessorImpl.invoke(Unknown Source)
	at sun.reflect.DelegatingMethodAccessorImpl.invoke(Unknown Source)
	at java.lang.reflect.Method.invoke(Unknown Source)
	at org.testng.internal.MethodInvocationHelper.invokeMethod(MethodInvocationHelper.java:86)
	at org.testng.internal.Invoker.invokeConfigurationMethod(Invoker.java:514)
	at org.testng.internal.Invoker.invokeConfigurations(Invoker.java:215)
	at org.testng.internal.Invoker.invokeConfigurations(Invoker.java:142)
	at org.testng.SuiteRunner.privateRun(SuiteRunner.java:336)
	at org.testng.SuiteRunner.run(SuiteRunner.java:268)
	at org.testng.SuiteRunnerWorker.runSuite(SuiteRunnerWorker.java:52)
	at org.testng.SuiteRunnerWorker.run(SuiteRunnerWorker.java:86)
	at org.testng.TestNG.runSuitesSequentially(TestNG.java:1244)
	at org.testng.TestNG.runSuitesLocally(TestNG.java:1169)
	at org.testng.TestNG.run(TestNG.java:1064)
	at org.testng.remote.AbstractRemoteTestNG.run(AbstractRemoteTestNG.java:114)
	at org.testng.remote.RemoteTestNG.initAndRun(RemoteTestNG.java:251)
	at org.testng.remote.RemoteTestNG.main(RemoteTestNG.java:77)
Caused by: org.hibernate.hql.internal.ast.QuerySyntaxException: customer is not mapped [delete from customer where username = 'username']
	at org.hibernate.hql.internal.ast.QuerySyntaxException.generateQueryException(QuerySyntaxException.java:79)
	at org.hibernate.QueryException.wrapWithQueryString(QueryException.java:103)
	at org.hibernate.hql.internal.ast.QueryTranslatorImpl.doCompile(QueryTranslatorImpl.java:217)
	at org.hibernate.hql.internal.ast.QueryTranslatorImpl.compile(QueryTranslatorImpl.java:141)
	at org.hibernate.engine.query.spi.HQLQueryPlan.<init>(HQLQueryPlan.java:115)
	at org.hibernate.engine.query.spi.HQLQueryPlan.<init>(HQLQueryPlan.java:77)
	at org.hibernate.engine.query.spi.QueryPlanCache.getHQLQueryPlan(QueryPlanCache.java:153)
	at org.hibernate.internal.AbstractSharedSessionContract.getQueryPlan(AbstractSharedSessionContract.java:545)
	at org.hibernate.internal.AbstractSharedSessionContract.createQuery(AbstractSharedSessionContract.java:654)
	... 20 more
Caused by: org.hibernate.hql.internal.ast.QuerySyntaxException: customer is not mapped
	at org.hibernate.hql.internal.ast.util.SessionFactoryHelper.requireClassPersister(SessionFactoryHelper.java:171)
	at org.hibernate.hql.internal.ast.tree.FromElementFactory.addFromElement(FromElementFactory.java:91)
	at org.hibernate.hql.internal.ast.tree.FromClause.addFromElement(FromClause.java:79)
	at org.hibernate.hql.internal.ast.HqlSqlWalker.createFromElement(HqlSqlWalker.java:321)
	at org.hibernate.hql.internal.antlr.HqlSqlBaseWalker.fromElement(HqlSqlBaseWalker.java:3690)
	at org.hibernate.hql.internal.antlr.HqlSqlBaseWalker.fromElementList(HqlSqlBaseWalker.java:3579)
	at org.hibernate.hql.internal.antlr.HqlSqlBaseWalker.fromClause(HqlSqlBaseWalker.java:718)
	at org.hibernate.hql.internal.antlr.HqlSqlBaseWalker.deleteStatement(HqlSqlBaseWalker.java:447)
	at org.hibernate.hql.internal.antlr.HqlSqlBaseWalker.statement(HqlSqlBaseWalker.java:275)
	at org.hibernate.hql.internal.ast.QueryTranslatorImpl.analyze(QueryTranslatorImpl.java:261)
	at org.hibernate.hql.internal.ast.QueryTranslatorImpl.doCompile(QueryTranslatorImpl.java:189)
	... 26 more
]]>
            </full-stacktrace>
          </exception> <!-- java.lang.IllegalArgumentException -->
          <reporter-output>
          </reporter-output>
        </test-method> <!-- deleteUser -->
      </class> <!-- daotests.CustomerDAOTesting -->
    </test> <!-- Default test -->
  </suite> <!-- Default suite -->
</testng-results>
